Workbook
Name senior_trips_2019: Inputs!$B$2
Name bus_rides_2019: Inputs!$B$3
Name card_senior: Inputs!$B$4
Name card_pwd: Inputs!$B$5
Name card_student: Inputs!$B$6
Name card_workfare: Inputs!$B$7
Name card_child: Inputs!$B$8
Name trips_2018: Inputs!$B$9
Name journeys_2018: Inputs!$B$10
Name share_senior: Inputs!$B$12
Name share_student: Inputs!$B$13
Name share_workfare: Inputs!$B$14
Name share_free: Inputs!$B$15
Name share_adult: Inputs!$B$16
Name transfer_share: Inputs!$B$17
Name income_p20: Inputs!$B$19
Name lta_daily: Inputs!$B$20
Name fre2025_inc: Inputs!$B$21
Name fre2026_inc: Inputs!$B$22
Name old_days: Inputs!$B$23
Name tel_rev: Inputs!$B$24
Name wd_bus_km: Inputs!$B$25
Name commuter_rides: Inputs!$B$26
Name adult_pass: Inputs!$B$27
Name g_rides: Inputs!$B$28
Name g_cost: Inputs!$B$29
Name later_fre: Inputs!$B$30
Name conc_change: Inputs!$B$31
Name bus_share: Inputs!$B$32
Name rides_total: Rides!$E$41
Name gross_now: Revenue!$D$41
Name adult_gross: Revenue!$E$41
Name gross_dec: Revenue!$H$41
Name mean_adult: Revenue!$D$43
Name rebate: Revenue!$D$44
Name tfactor: Revenue!$D$45
Name rev_now: Revenue!$D$46
Name rev_dec: Revenue!$D$47
Name dec_change: Revenue!$D$48
Name dec_increase: Revenue!$D$49
Name fy25_fare: Fund!$B$2
Name fy25_fees: Fund!$E$2
Name fy25_opex: Fund!$F$2
Name rec_rides_ratio: Reconciliation!$D$2
Name pub_adj: Reconciliation!$C$3
Name rec_rev_ratio: Reconciliation!$D$3
Name rec_dec_ratio: Reconciliation!$D$5
Name implied_yield: Reconciliation!$B$7
Name fee_service_year: Contracts!$G$12
Name fee_per_bus_km: Contracts!$G$13
Name fre2025_full: Projection!$B$10
Name deficit_fy2030: Projection!$G$7
Name fare_fy2030: Projection!$D$7
Name fare_fy2026: Projection!$D$3
Name conc_delta: Scenarios!$B$13
Name flat_fare: Scenarios!$B$16
Name flat_more: Scenarios!$B$17
Name spend_median_now: Scenarios!$C$21
Name spend_p90_dec: Scenarios!$D$22
Name spend_p90_dec_income: Scenarios!$G$22

Sheet README
A1: Singapore bus finance and fare model (public data only)
A3: Blue cells are inputs; every other number is a live formula. Change an input and the model recalculates.
A4: Rides: DataMall origin-destination volumes, July and August 2026, scaled to 2026 day counts (Rides sheet).
A5: Fares: PTC card fare tables in force from 27 Dec 2025 and approved for 26 Dec 2026 (Fares sheet).
A6: Published figures: LTA audited Bus Contracting accounts, LTA ridership statistics, PTC fare reviews, LTA contract award releases (Sources sheet, with the quoted text).
A7: Fare-group shares and the transfer share are derived from published counts under stated assumptions (Inputs sheet).
A8: Monthly passes, cash fares (<1% of journeys), express surcharges on mixed pairs and fare evasion are not modelled separately.
A9: Built by src/finance_workbook.py; src/finance_model.py computes the same headline cells in Python and the test suite checks that the two agree.

Sheet Inputs
A1: Input | B1: Value | C1: Unit | D1: Source / note
A2: Bus rides a day on senior concession cards, 2019 | B2: 743000 | C2: rides/day | D2: MOT written reply: bus trips a day on Senior Citizen Concession Cards, 743,000 in 2019
A3: LTA average daily public bus ridership, 2019 | B3: 4099000 | C3: rides/day | D3: LTA, Public Transport Ridership - Average Daily Ridership 2015-2025: bus 4,099 thousand in 2019
A4: Share of concession cards: senior | B4: 0.47 | C4: share | D4: MOT written reply (cards valid at end June 2021): seniors 47%, students 31%, child 6%, adult monthly travel cards 3%, NSF 3%, Workfare 9%, PwD 1%
A5: Share of concession cards: pwd | B5: 0.01 | C5: share | D5: MOT written reply (cards valid at end June 2021): seniors 47%, students 31%, child 6%, adult monthly travel cards 3%, NSF 3%, Workfare 9%, PwD 1%
A6: Share of concession cards: student | B6: 0.31 | C6: share | D6: MOT written reply (cards valid at end June 2021): seniors 47%, students 31%, child 6%, adult monthly travel cards 3%, NSF 3%, Workfare 9%, PwD 1%
A7: Share of concession cards: workfare | B7: 0.09 | C7: share | D7: MOT written reply (cards valid at end June 2021): seniors 47%, students 31%, child 6%, adult monthly travel cards 3%, NSF 3%, Workfare 9%, PwD 1%
A8: Share of concession cards: child | B8: 0.06 | C8: share | D8: MOT written reply (cards valid at end June 2021): seniors 47%, students 31%, child 6%, adult monthly travel cards 3%, NSF 3%, Workfare 9%, PwD 1%
A9: Smart-card trips on a weekday (bus + rail, Feb 2018) | B9: 6200000 | C9: trips/day | D9: arXiv 2509.13633 (academic preprint): a typical weekday in February 2018 had about 6.2 million trips, i.e. 4.5 million journeys (bus and rail)
A10: Linked journeys on that weekday | B10: 4500000 | C10: journeys/day | D10: arXiv 2509.13633 (academic preprint): a typical weekday in February 2018 had about 6.2 million trips, i.e. 4.5 million journeys (bus and rail)
A11: Derived shares of bus rides (formulas). Assumes rides per card are the same in every concession group, calibrated on seniors; children under 7 ride free.
A12: Share of rides paying Senior / PwD fares | B12: =senior_trips_2019/bus_rides_2019*(card_senior+card_pwd)/card_senior
A13: Share of rides paying Student fares | B13: =senior_trips_2019/bus_rides_2019*card_student/card_senior
A14: Share of rides paying Workfare (WTCS) fares | B14: =senior_trips_2019/bus_rides_2019*card_workfare/card_senior
A15: Share of rides that are free (children under 7) | B15: =senior_trips_2019/bus_rides_2019*card_child/card_senior
A16: Share of rides paying Adult fares (the rest) | B16: =1-share_senior-share_student-share_workfare-share_free
A17: Share of rides that are a transfer leg (1 - journeys / trips) | B17: =1-journeys_2018/trips_2018 | D17: Bus and rail combined; used for bus rides as an approximation
A19: 20th percentile monthly household market income, 2025 | B19: 4329 | C19: S$/month | D19: SingStat table C030012: 20th percentile monthly household market income, resident households, 2025
A20: LTA average daily public bus ridership, 2025 | B20: 3841000 | C20: rides/day | D20: LTA, Public Transport Ridership - Average Daily Ridership 2015-2025 (bus 2025: 3,841 thousand); same series on data.gov.sg d_ba615ec4cc5d9f5b7800ad82057f36f1
A21: FRE 2025 extra fare revenue, bus + TEL, per year | B21: 62300000 | C21: S$/yr | D21: PTC FRE 2025 Annex A: fare revenues for bus and TEL collected by LTA will increase by $62.3 million
A22: FRE 2026 extra fare revenue, bus + TEL, per year | B22: 97100000 | C22: S$/yr | D22: PTC FRE 2026 Annex A: bus and TEL fare revenue collected by LTA increases by $97.1 million
A23: Days of FY2025/26 at the old (Dec 2024) fares | B23: 270 | C23: days | D23: 1 Apr 2025 to 26 Dec 2025; the 2025 fare review took effect on 27 Dec 2025
A24: Rail contracting (TEL/JRL) fare revenue, FY2025/26 | B24: 76000000 | C24: S$ | D24: LTA FY2025/26 financial statements: Rail Contracting (TEL/JRL) fare revenue $76m
A25: Scheduled weekday bus-km per day (DataMall timetable bands) | B25: 910617.82 | C25: bus-km/day | D25: finance.py: route length x scheduled trips from headway bands and first/last bus; weekday timetable
A26: Rides a month for a regular commuter | B26: 44 | C26: rides | D26: 2 rides a working day x 22 days (illustrative)
A27: Adult Monthly Travel Pass (bus + train), from 27 Dec 2025 | B27: 122 | C27: S$/month | D27: PTC FRE 2025 Annex B
A28: Ridership growth per year (projection) | B28: 0.012465672 | C28: share | D28: Average 2023-2025 growth of LTA average daily bus ridership (3,747k to 3,841k)
A29: Operating cost growth per year (projection) | B29: 0.01943816 | C29: share | D29: Average FY2020/21-FY2025/26 growth of Bus Contracting total operating expenditure (S$1,821m to S$2,005m)
A30: Fare change at each later fare review (projection, FY2027 on) | B30: 0 | C30: share | D30: Not decided; 0% by default. Fare reviews take effect in late December.
A31: Concession scenario: change in senior / PwD fares | B31: -0.1 | C31: share | D31: Illustrative policy test
A32: Bus share of bus + TEL fare revenue, FY2025/26 | B32: =Fund!B2/(Fund!B2+tel_rev/1000000) | D32: Fund sheet (bus) and the rail contracting note

Sheet Fares
A1: Band | B1: Fare km (ride-weighted mean of trunk rides) | C1: Adult trunk (now) | D1: Adult express (now) | E1: Senior / PwD trunk (now) | F1: Senior / PwD express (now) | G1: Student trunk (now) | H1: Student express (now) | I1: Workfare (WTCS) trunk (now) | J1: Workfare (WTCS) express (now) | K1: Adult trunk (Dec 2026) | L1: Adult express (Dec 2026) | M1: Senior / PwD trunk (Dec 2026) | N1: Senior / PwD express (Dec 2026) | O1: Student trunk (Dec 2026) | P1: Student express (Dec 2026) | Q1: Workfare (WTCS) trunk (Dec 2026) | R1: Workfare (WTCS) express (Dec 2026)
A2: Up to 3.2 km | B2: 1.6103063 | C2: 128 | D2: 228 | E2: 69 | F2: 134 | G2: 52 | H2: 102 | I2: 78 | J2: 148 | K2: 140 | L2: 240 | M2: 74 | N2: 139 | O2: 57 | P2: 107 | Q2: 78 | R2: 148
A3: 3.3 km - 4.2 km | B3: 3.7253371 | C3: 138 | D3: 238 | E3: 79 | F3: 144 | G3: 60 | H3: 110 | I3: 89 | J3: 159 | K3: 151 | L3: 251 | M3: 84 | N3: 149 | O3: 65 | P3: 115 | Q3: 89 | R3: 159
A4: 4.3 km - 5.2 km | B4: 4.7204642 | C4: 149 | D4: 249 | E4: 87 | F4: 152 | G4: 66 | H4: 116 | I4: 98 | J4: 168 | K4: 162 | L4: 262 | M4: 92 | N4: 157 | O4: 71 | P4: 121 | Q4: 98 | R4: 168
A5: 5.3 km - 6.2 km | B5: 5.7299317 | C5: 159 | D5: 259 | E5: 94 | F5: 159 | G5: 71 | H5: 121 | I5: 106 | J5: 176 | K5: 172 | L5: 272 | M5: 99 | N5: 164 | O5: 76 | P5: 126 | Q5: 106 | R5: 176
A6: 6.3 km - 7.2 km | B6: 6.7388984 | C6: 168 | D6: 268 | E6: 100 | F6: 165 | G6: 74 | H6: 124 | I6: 113 | J6: 183 | K6: 181 | L6: 281 | M6: 105 | N6: 170 | O6: 79 | P6: 129 | Q6: 113 | R6: 183
A7: 7.3 km - 8.2 km | B7: 7.7298657 | C7: 175 | D7: 275 | E7: 107 | F7: 172 | G7: 78 | H7: 128 | I7: 120 | J7: 190 | K7: 188 | L7: 288 | M7: 112 | N7: 177 | O7: 83 | P7: 133 | Q7: 120 | R7: 190
A8: 8.3 km - 9.2 km | B8: 8.7343699 | C8: 182 | D8: 282 | E8: 107 | F8: 172 | G8: 78 | H8: 128 | I8: 126 | J8: 196 | K8: 195 | L8: 295 | M8: 112 | N8: 177 | O8: 83 | P8: 133 | Q8: 126 | R8: 196
A9: 9.3 km - 10.2 km | B9: 9.729266 | C9: 186 | D9: 286 | E9: 107 | F9: 172 | G9: 78 | H9: 128 | I9: 129 | J9: 199 | K9: 199 | L9: 299 | M9: 112 | N9: 177 | O9: 83 | P9: 133 | Q9: 129 | R9: 199
A10: 10.3 km - 11.2 km | B10: 10.731775 | C10: 190 | D10: 290 | E10: 107 | F10: 172 | G10: 78 | H10: 128 | I10: 132 | J10: 202 | K10: 203 | L10: 303 | M10: 112 | N10: 177 | O10: 83 | P10: 133 | Q10: 132 | R10: 202
A11: 11.3 km - 12.2 km | B11: 11.720889 | C11: 194 | D11: 294 | E11: 107 | F11: 172 | G11: 78 | H11: 128 | I11: 135 | J11: 205 | K11: 207 | L11: 307 | M11: 112 | N11: 177 | O11: 83 | P11: 133 | Q11: 135 | R11: 205
A12: 12.3 km - 13.2 km | B12: 12.734004 | C12: 198 | D12: 298 | E12: 107 | F12: 172 | G12: 78 | H12: 128 | I12: 138 | J12: 208 | K12: 211 | L12: 311 | M12: 112 | N12: 177 | O12: 83 | P12: 133 | Q12: 138 | R12: 208
A13: 13.3 km - 14.2 km | B13: 13.72028 | C13: 202 | D13: 302 | E13: 107 | F13: 172 | G13: 78 | H13: 128 | I13: 141 | J13: 211 | K13: 215 | L13: 315 | M13: 112 | N13: 177 | O13: 83 | P13: 133 | Q13: 141 | R13: 211
... A40: Over 40.2 km | B40: 49.324685 | C40: 257 | D40: 357 | E40: 107 | F40: 172 | G40: 78 | H40: 128 | I40: 187 | J40: 257 | K40: 270 | L40: 370 | M40: 112 | N40: 177 | O40: 83 | P40: 133 | Q40: 187 | R40: 257
A42: Feeder (flat) | C42: 128 | E42: 69 | G42: 52 | I42: 78 | K42: 140 | M42: 74 | O42: 57 | Q42: 78
A44: Cents per ride, card fares. Concession tables stop at 'Over 7.2 km'; longer bands repeat that fare. Source: PTC FRE 2025 and FRE 2026 annexes (Sources sheet).

Sheet Rides
A1: Band | B1: Trunk rides / yr | C1: Feeder rides / yr | D1: Express rides / yr | E1: All
A2: Up to 3.2 km | B2: 8.061864e+08 | C2: 1.8635528e+08 | D2: 259933.99 | E2: =SUM(B2:D2)
A3: 3.3 km - 4.2 km | B3: 1.1695367e+08 | C3: 0 | D3: 139874.22 | E3: =SUM(B3:D3)
A4: 4.3 km - 5.2 km | B4: 75105202 | C4: 0 | D4: 121220.97 | E4: =SUM(B4:D4)
A5: 5.3 km - 6.2 km | B5: 52445883 | C5: 0 | D5: 119022.52 | E5: =SUM(B5:D5)
A6: 6.3 km - 7.2 km | B6: 38814733 | C6: 0 | D6: 62107.335 | E6: =SUM(B6:D6)
A7: 7.3 km - 8.2 km | B7: 31662389 | C7: 0 | D7: 56103.662 | E7: =SUM(B7:D7)
A8: 8.3 km - 9.2 km | B8: 25312289 | C8: 0 | D8: 39456.759 | E8: =SUM(B8:D8)
A9: 9.3 km - 10.2 km | B9: 20045192 | C9: 0 | D9: 33516.742 | E9: =SUM(B9:D9)
A10: 10.3 km - 11.2 km | B10: 15977469 | C10: 0 | D10: 51859.569 | E10: =SUM(B10:D10)
A11: 11.3 km - 12.2 km | B11: 13346304 | C11: 0 | D11: 136200.96 | E11: =SUM(B11:D11)
A12: 12.3 km - 13.2 km | B12: 11036760 | C12: 0 | D12: 203276.06 | E12: =SUM(B12:D12)
A13: 13.3 km - 14.2 km | B13: 10072068 | C13: 0 | D13: 256619.35 | E13: =SUM(B13:D13)
... A40: Over 40.2 km | B40: 11423.664 | C40: 0 | D40: 3164.1387 | E40: =SUM(B40:D40)
A41: Total | B41: =SUM(B2:B40) | C41: =SUM(C2:C40) | D41: =SUM(D2:D40) | E41: =SUM(E2:E40)
A43: Annual rides = mean of July and August 2026 rides per day by day type x 2026 day counts (251 weekdays, 114 weekend days and holidays). Fare km = along-route distance on the cheapest service serving the stop pair.

Sheet Revenue
A1: Band | B1: Blended trunk fare now (c) | C1: Blended express fare now (c) | D1: Revenue now (S$) | E1: Adult-fare revenue now (S$) | F1: Blended trunk fare Dec 2026 (c) | G1: Blended express fare Dec 2026 (c) | H1: Revenue Dec 2026 (S$) | I1: Adult trunk fare now (c) | J1: Revenue with the concession test (S$)
A2: Up to 3.2 km | B2: =share_adult*Fares!C2+share_senior*Fares!E2+share_student*Fares!G2+share_workfare*Fares!I2 | C2: =share_adult*Fares!D2+share_senior*Fares!F2+share_student*Fares!H2+share_workfare*Fares!J2 | D2: =(Rides!B2*B2+Rides!C2*(share_adult*Fares!$C$42+share_senior*Fares!$E$42+share_student*Fares!$G$42+share_workfare*Fares!$I$42)+Rides!D2*C2)/100 | E2: =(Rides!B2*Fares!C2+Rides!C2*Fares!$C$42+Rides!D2*Fares!D2)/100 | F2: =share_adult*Fares!K2+share_senior*Fares!M2+share_student*Fares!O2+share_workfare*Fares!Q2 | G2: =share_adult*Fares!L2+share_senior*Fares!N2+share_student*Fares!P2+share_workfare*Fares!R2 | H2: =(Rides!B2*F2+Rides!C2*(share_adult*Fares!$K$42+share_senior*Fares!$M$42+share_student*Fares!$O$42+share_workfare*Fares!$Q$42)+Rides!D2*G2)/100 | I2: =Fares!C2 | J2: =(Rides!B2*(share_adult*Fares!C2+share_senior*Fares!E2*(1+conc_change)+share_student*Fares!G2+share_workfare*Fares!I2)+Rides!C2*(share_adult*Fares!$C$42+share_senior*Fares!$E$42*(1+conc_change)+share_student*Fares!$G$42+share_workfare*Fares!$I$42)+Rides!D2*(share_adult*Fares!D2+share_senior*Fares!F2*(1+conc_change)+share_student*Fares!H2+share_workfare*Fares!J2))/100
A3: 3.3 km - 4.2 km | B3: =share_adult*Fares!C3+share_senior*Fares!E3+share_student*Fares!G3+share_workfare*Fares!I3 | C3: =share_adult*Fares!D3+share_senior*Fares!F3+share_student*Fares!H3+share_workfare*Fares!J3 | D3: =(Rides!B3*B3+Rides!C3*0+Rides!D3*C3)/100 | E3: =(Rides!B3*Fares!C3+Rides!C3*0+Rides!D3*Fares!D3)/100 | F3: =share_adult*Fares!K3+share_senior*Fares!M3+share_student*Fares!O3+share_workfare*Fares!Q3 | G3: =share_adult*Fares!L3+share_senior*Fares!N3+share_student*Fares!P3+share_workfare*Fares!R3 | H3: =(Rides!B3*F3+Rides!C3*0+Rides!D3*G3)/100 | I3: =Fares!C3 | J3: =(Rides!B3*(share_adult*Fares!C3+share_senior*Fares!E3*(1+conc_change)+share_student*Fares!G3+share_workfare*Fares!I3)+Rides!C3*0+Rides!D3*(share_adult*Fares!D3+share_senior*Fares!F3*(1+conc_change)+share_student*Fares!H3+share_workfare*Fares!J3))/100
A4: 4.3 km - 5.2 km | B4: =share_adult*Fares!C4+share_senior*Fares!E4+share_student*Fares!G4+share_workfare*Fares!I4 | C4: =share_adult*Fares!D4+share_senior*Fares!F4+share_student*Fares!H4+share_workfare*Fares!J4 | D4: =(Rides!B4*B4+Rides!C4*0+Rides!D4*C4)/100 | E4: =(Rides!B4*Fares!C4+Rides!C4*0+Rides!D4*Fares!D4)/100 | F4: =share_adult*Fares!K4+share_senior*Fares!M4+share_student*Fares!O4+share_workfare*Fares!Q4 | G4: =share_adult*Fares!L4+share_senior*Fares!N4+share_student*Fares!P4+share_workfare*Fares!R4 | H4: =(Rides!B4*F4+Rides!C4*0+Rides!D4*G4)/100 | I4: =Fares!C4 | J4: =(Rides!B4*(share_adult*Fares!C4+share_senior*Fares!E4*(1+conc_change)+share_student*Fares!G4+share_workfare*Fares!I4)+Rides!C4*0+Rides!D4*(share_adult*Fares!D4+share_senior*Fares!F4*(1+conc_change)+share_student*Fares!H4+share_workfare*Fares!J4))/100
A5: 5.3 km - 6.2 km | B5: =share_adult*Fares!C5+share_senior*Fares!E5+share_student*Fares!G5+share_workfare*Fares!I5 | C5: =share_adult*Fares!D5+share_senior*Fares!F5+share_student*Fares!H5+share_workfare*Fares!J5 | D5: =(Rides!B5*B5+Rides!C5*0+Rides!D5*C5)/100 | E5: =(Rides!B5*Fares!C5+Rides!C5*0+Rides!D5*Fares!D5)/100 | F5: =share_adult*Fares!K5+share_senior*Fares!M5+share_student*Fares!O5+share_workfare*Fares!Q5 | G5: =share_adult*Fares!L5+share_senior*Fares!N5+share_student*Fares!P5+share_workfare*Fares!R5 | H5: =(Rides!B5*F5+Rides!C5*0+Rides!D5*G5)/100 | I5: =Fares!C5 | J5: =(Rides!B5*(share_adult*Fares!C5+share_senior*Fares!E5*(1+conc_change)+share_student*Fares!G5+share_workfare*Fares!I5)+Rides!C5*0+Rides!D5*(share_adult*Fares!D5+share_senior*Fares!F5*(1+conc_change)+share_student*Fares!H5+share_workfare*Fares!J5))/100
A6: 6.3 km - 7.2 km | B6: =share_adult*Fares!C6+share_senior*Fares!E6+share_student*Fares!G6+share_workfare*Fares!I6 | C6: =share_adult*Fares!D6+share_senior*Fares!F6+share_student*Fares!H6+share_workfare*Fares!J6 | D6: =(Rides!B6*B6+Rides!C6*0+Rides!D6*C6)/100 | E6: =(Rides!B6*Fares!C6+Rides!C6*0+Rides!D6*Fares!D6)/100 | F6: =share_adult*Fares!K6+share_senior*Fares!M6+share_student*Fares!O6+share_workfare*Fares!Q6 | G6: =share_adult*Fares!L6+share_senior*Fares!N6+share_student*Fares!P6+share_workfare*Fares!R6 | H6: =(Rides!B6*F6+Rides!C6*0+Rides!D6*G6)/100 | I6: =Fares!C6 | J6: =(Rides!B6*(share_adult*Fares!C6+share_senior*Fares!E6*(1+conc_change)+share_student*Fares!G6+share_workfare*Fares!I6)+Rides!C6*0+Rides!D6*(share_adult*Fares!D6+share_senior*Fares!F6*(1+conc_change)+share_student*Fares!H6+share_workfare*Fares!J6))/100
A7: 7.3 km - 8.2 km | B7: =share_adult*Fares!C7+share_senior*Fares!E7+share_student*Fares!G7+share_workfare*Fares!I7 | C7: =share_adult*Fares!D7+share_senior*Fares!F7+share_student*Fares!H7+share_workfare*Fares!J7 | D7: =(Rides!B7*B7+Rides!C7*0+Rides!D7*C7)/100 | E7: =(Rides!B7*Fares!C7+Rides!C7*0+Rides!D7*Fares!D7)/100 | F7: =share_adult*Fares!K7+share_senior*Fares!M7+share_student*Fares!O7+share_workfare*Fares!Q7 | G7: =share_adult*Fares!L7+share_senior*Fares!N7+share_student*Fares!P7+share_workfare*Fares!R7 | H7: =(Rides!B7*F7+Rides!C7*0+Rides!D7*G7)/100 | I7: =Fares!C7 | J7: =(Rides!B7*(share_adult*Fares!C7+share_senior*Fares!E7*(1+conc_change)+share_student*Fares!G7+share_workfare*Fares!I7)+Rides!C7*0+Rides!D7*(share_adult*Fares!D7+share_senior*Fares!F7*(1+conc_change)+share_student*Fares!H7+share_workfare*Fares!J7))/100
A8: 8.3 km - 9.2 km | B8: =share_adult*Fares!C8+share_senior*Fares!E8+share_student*Fares!G8+share_workfare*Fares!I8 | C8: =share_adult*Fares!D8+share_senior*Fares!F8+share_student*Fares!H8+share_workfare*Fares!J8 | D8: =(Rides!B8*B8+Rides!C8*0+Rides!D8*C8)/100 | E8: =(Rides!B8*Fares!C8+Rides!C8*0+Rides!D8*Fares!D8)/100 | F8: =share_adult*Fares!K8+share_senior*Fares!M8+share_student*Fares!O8+share_workfare*Fares!Q8 | G8: =share_adult*Fares!L8+share_senior*Fares!N8+share_student*Fares!P8+share_workfare*Fares!R8 | H8: =(Rides!B8*F8+Rides!C8*0+Rides!D8*G8)/100 | I8: =Fares!C8 | J8: =(Rides!B8*(share_adult*Fares!C8+share_senior*Fares!E8*(1+conc_change)+share_student*Fares!G8+share_workfare*Fares!I8)+Rides!C8*0+Rides!D8*(share_adult*Fares!D8+share_senior*Fares!F8*(1+conc_change)+share_student*Fares!H8+share_workfare*Fares!J8))/100
A9: 9.3 km - 10.2 km | B9: =share_adult*Fares!C9+share_senior*Fares!E9+share_student*Fares!G9+share_workfare*Fares!I9 | C9: =share_adult*Fares!D9+share_senior*Fares!F9+share_student*Fares!H9+share_workfare*Fares!J9 | D9: =(Rides!B9*B9+Rides!C9*0+Rides!D9*C9)/100 | E9: =(Rides!B9*Fares!C9+Rides!C9*0+Rides!D9*Fares!D9)/100 | F9: =share_adult*Fares!K9+share_senior*Fares!M9+share_student*Fares!O9+share_workfare*Fares!Q9 | G9: =share_adult*Fares!L9+share_senior*Fares!N9+share_student*Fares!P9+share_workfare*Fares!R9 | H9: =(Rides!B9*F9+Rides!C9*0+Rides!D9*G9)/100 | I9: =Fares!C9 | J9: =(Rides!B9*(share_adult*Fares!C9+share_senior*Fares!E9*(1+conc_change)+share_student*Fares!G9+share_workfare*Fares!I9)+Rides!C9*0+Rides!D9*(share_adult*Fares!D9+share_senior*Fares!F9*(1+conc_change)+share_student*Fares!H9+share_workfare*Fares!J9))/100
A10: 10.3 km - 11.2 km | B10: =share_adult*Fares!C10+share_senior*Fares!E10+share_student*Fares!G10+share_workfare*Fares!I10 | C10: =share_adult*Fares!D10+share_senior*Fares!F10+share_student*Fares!H10+share_workfare*Fares!J10 | D10: =(Rides!B10*B10+Rides!C10*0+Rides!D10*C10)/100 | E10: =(Rides!B10*Fares!C10+Rides!C10*0+Rides!D10*Fares!D10)/100 | F10: =share_adult*Fares!K10+share_senior*Fares!M10+share_student*Fares!O10+share_workfare*Fares!Q10 | G10: =share_adult*Fares!L10+share_senior*Fares!N10+share_student*Fares!P10+share_workfare*Fares!R10 | H10: =(Rides!B10*F10+Rides!C10*0+Rides!D10*G10)/100 | I10: =Fares!C10 | J10: =(Rides!B10*(share_adult*Fares!C10+share_senior*Fares!E10*(1+conc_change)+share_student*Fares!G10+share_workfare*Fares!I10)+Rides!C10*0+Rides!D10*(share_adult*Fares!D10+share_senior*Fares!F10*(1+conc_change)+share_student*Fares!H10+share_workfare*Fares!J10))/100
A11: 11.3 km - 12.2 km | B11: =share_adult*Fares!C11+share_senior*Fares!E11+share_student*Fares!G11+share_workfare*Fares!I11 | C11: =share_adult*Fares!D11+share_senior*Fares!F11+share_student*Fares!H11+share_workfare*Fares!J11 | D11: =(Rides!B11*B11+Rides!C11*0+Rides!D11*C11)/100 | E11: =(Rides!B11*Fares!C11+Rides!C11*0+Rides!D11*Fares!D11)/100 | F11: =share_adult*Fares!K11+share_senior*Fares!M11+share_student*Fares!O11+share_workfare*Fares!Q11 | G11: =share_adult*Fares!L11+share_senior*Fares!N11+share_student*Fares!P11+share_workfare*Fares!R11 | H11: =(Rides!B11*F11+Rides!C11*0+Rides!D11*G11)/100 | I11: =Fares!C11 | J11: =(Rides!B11*(share_adult*Fares!C11+share_senior*Fares!E11*(1+conc_change)+share_student*Fares!G11+share_workfare*Fares!I11)+Rides!C11*0+Rides!D11*(share_adult*Fares!D11+share_senior*Fares!F11*(1+conc_change)+share_student*Fares!H11+share_workfare*Fares!J11))/100
A12: 12.3 km - 13.2 km | B12: =share_adult*Fares!C12+share_senior*Fares!E12+share_student*Fares!G12+share_workfare*Fares!I12 | C12: =share_adult*Fares!D12+share_senior*Fares!F12+share_student*Fares!H12+share_workfare*Fares!J12 | D12: =(Rides!B12*B12+Rides!C12*0+Rides!D12*C12)/100 | E12: =(Rides!B12*Fares!C12+Rides!C12*0+Rides!D12*Fares!D12)/100 | F12: =share_adult*Fares!K12+share_senior*Fares!M12+share_student*Fares!O12+share_workfare*Fares!Q12 | G12: =share_adult*Fares!L12+share_senior*Fares!N12+share_student*Fares!P12+share_workfare*Fares!R12 | H12: =(Rides!B12*F12+Rides!C12*0+Rides!D12*G12)/100 | I12: =Fares!C12 | J12: =(Rides!B12*(share_adult*Fares!C12+share_senior*Fares!E12*(1+conc_change)+share_student*Fares!G12+share_workfare*Fares!I12)+Rides!C12*0+Rides!D12*(share_adult*Fares!D12+share_senior*Fares!F12*(1+conc_change)+share_student*Fares!H12+share_workfare*Fares!J12))/100
A13: 13.3 km - 14.2 km | B13: =share_adult*Fares!C13+share_senior*Fares!E13+share_student*Fares!G13+share_workfare*Fares!I13 | C13: =share_adult*Fares!D13+share_senior*Fares!F13+share_student*Fares!H13+share_workfare*Fares!J13 | D13: =(Rides!B13*B13+Rides!C13*0+Rides!D13*C13)/100 | E13: =(Rides!B13*Fares!C13+Rides!C13*0+Rides!D13*Fares!D13)/100 | F13: =share_adult*Fares!K13+share_senior*Fares!M13+share_student*Fares!O13+share_workfare*Fares!Q13 | G13: =share_adult*Fares!L13+share_senior*Fares!N13+share_student*Fares!P13+share_workfare*Fares!R13 | H13: =(Rides!B13*F13+Rides!C13*0+Rides!D13*G13)/100 | I13: =Fares!C13 | J13: =(Rides!B13*(share_adult*Fares!C13+share_senior*Fares!E13*(1+conc_change)+share_student*Fares!G13+share_workfare*Fares!I13)+Rides!C13*0+Rides!D13*(share_adult*Fares!D13+share_senior*Fares!F13*(1+conc_change)+share_student*Fares!H13+share_workfare*Fares!J13))/100
A14: 14.3 km - 15.2 km | B14: =share_adult*Fares!C14+share_senior*Fares!E14+share_student*Fares!G14+share_workfare*Fares!I14 | C14: =share_adult*Fares!D14+share_senior*Fares!F14+share_student*Fares!H14+share_workfare*Fares!J14 | D14: =(Rides!B14*B14+Rides!C14*0+Rides!D14*C14)/100 | E14: =(Rides!B14*Fares!C14+Rides!C14*0+Rides!D14*Fares!D14)/100 | F14: =share_adult*Fares!K14+share_senior*Fares!M14+share_student*Fares!O14+share_workfare*Fares!Q14 | G14: =share_adult*Fares!L14+share_senior*Fares!N14+share_student*Fares!P14+share_workfare*Fares!R14 | H14: =(Rides!B14*F14+Rides!C14*0+Rides!D14*G14)/100 | I14: =Fares!C14 | J14: =(Rides!B14*(share_adult*Fares!C14+share_senior*Fares!E14*(1+conc_change)+share_student*Fares!G14+share_workfare*Fares!I14)+Rides!C14*0+Rides!D14*(share_adult*Fares!D14+share_senior*Fares!F14*(1+conc_change)+share_student*Fares!H14+share_workfare*Fares!J14))/100
... A40: Over 40.2 km | B40: =share_adult*Fares!C40+share_senior*Fares!E40+share_student*Fares!G40+share_workfare*Fares!I40 | C40: =share_adult*Fares!D40+share_senior*Fares!F40+share_student*Fares!H40+share_workfare*Fares!J40 | D40: =(Rides!B40*B40+Rides!C40*0+Rides!D40*C40)/100 | E40: =(Rides!B40*Fares!C40+Rides!C40*0+Rides!D40*Fares!D40)/100 | F40: =share_adult*Fares!K40+share_senior*Fares!M40+share_student*Fares!O40+share_workfare*Fares!Q40 | G40: =share_adult*Fares!L40+share_senior*Fares!N40+share_student*Fares!P40+share_workfare*Fares!R40 | H40: =(Rides!B40*F40+Rides!C40*0+Rides!D40*G40)/100 | I40: =Fares!C40 | J40: =(Rides!B40*(share_adult*Fares!C40+share_senior*Fares!E40*(1+conc_change)+share_student*Fares!G40+share_workfare*Fares!I40)+Rides!C40*0+Rides!D40*(share_adult*Fares!D40+share_senior*Fares!F40*(1+conc_change)+share_student*Fares!H40+share_workfare*Fares!J40))/100
A41: Total | D41: =SUM(D2:D40) | E41: =SUM(E2:E40) | H41: =SUM(H2:H40) | J41: =SUM(J2:J40)
A43: Mean adult fare per ride (cents) | D43: =adult_gross*100/rides_total
A44: Average transfer rebate F(a)+F(b)-F(a+b) (cents, Transfers sheet) | D44: =Transfers!B1
A45: Transfer factor (journey fares / ride fares) | D45: =1-transfer_share*rebate/mean_adult
A46: Estimated fare revenue at current fares (S$/yr) | D46: =gross_now*tfactor
A47: Estimated fare revenue at Dec 2026 fares (S$/yr) | D47: =gross_dec*tfactor
A48: Change from the Dec 2026 fare review | D48: =rev_dec/rev_now-1
A49: Extra revenue a year from the Dec 2026 fare review (S$) | D49: =rev_dec-rev_now
A50: Revenue if every ride paid the adult fare, no transfers (S$/yr) | D50: =adult_gross

Sheet Transfers
A1: Expected rebate per transfer (cents) | B1: =SUM(B4:AN42)
A2: Cell (a, b) = P(a) P(b) [F(a) + F(b) - F(band of km_a + km_b)], adult trunk fares, P = share of trunk rides in each band, km = Fares!B.
B3: =Fares!$B$2 | C3: =Fares!$B$3 | D3: =Fares!$B$4 | E3: =Fares!$B$5 | F3: =Fares!$B$6 | G3: =Fares!$B$7 | H3: =Fares!$B$8 | I3: =Fares!$B$9 | J3: =Fares!$B$10 | K3: =Fares!$B$11 | L3: =Fares!$B$12 | M3: =Fares!$B$13 | N3: =Fares!$B$14 | O3: =Fares!$B$15 | P3: =Fares!$B$16 | Q3: =Fares!$B$17 | R3: =Fares!$B$18 | S3: =Fares!$B$19 | T3: =Fares!$B$20 | U3: =Fares!$B$21 | V3: =Fares!$B$22 | W3: =Fares!$B$23 | X3: =Fares!$B$24 | Y3: =Fares!$B$25 | Z3: =Fares!$B$26 | AA3: =Fares!$B$27 | AB3: =Fares!$B$28 | AC3: =Fares!$B$29 | AD3: =Fares!$B$30 | AE3: =Fares!$B$31 | AF3: =Fares!$B$32 | AG3: =Fares!$B$33 | AH3: =Fares!$B$34 | AI3: =Fares!$B$35 | AJ3: =Fares!$B$36 | AK3: =Fares!$B$37 | AL3: =Fares!$B$38 | AM3: =Fares!$B$39 | AN3: =Fares!$B$40
A4: =Fares!$B$2 | B4: =Rides!$B$2/Rides!$B$41*Rides!$B$2/Rides!$B$41*(Fares!$C$2+Fares!$C$2-INDEX(Fares!$C$2:$C$40,MIN(38,MAX(0,ROUNDUP(ROUND(Fares!$B$2+Fares!$B$2-3.2,1)-0.000000001,0)))+1)) | C4: =Rides!$B$2/Rides!$B$41*Rides!$B$3/Rides!$B$41*(Fares!$C$2+Fares!$C$3-INDEX(Fares!$C$2:$C$40,MIN(38,MAX(0,ROUNDUP(ROUND(Fares!$B$2+Fares!$B$3-3.2,1)-0.000000001,0)))+1)) | D4: =Rides!$B$2/Rides!$B$41*Rides!$B$4/Rides!$B$41*(Fares!$C$2+Fares!$C$4-INDEX(Fares!$C$2:$C$40,MIN(38,MAX(0,ROUNDUP(ROUND(Fares!$B$2+Fares!$B$4-3.2,1)-0.000000001,0)))+1)) | E4: =Rides!$B$2/Rides!$B$41*Rides!$B$5/Rides!$B$41*(Fares!$C$2+Fares!$C$5-INDEX(Fares!$C$2:$C$40,MIN(38,MAX(0,ROUNDUP(ROUND(Fares!$B$2+Fares!$B$5-3.2,1)-0.000000001,0)))+1)) | F4: =Rides!$B$2/Rides!$B$41*Rides!$B$6/Rides!$B$41*(Fares!$C$2+Fares!$C$6-INDEX(Fares!$C$2:$C$40,MIN(38,MAX(0,ROUNDUP(ROUND(Fares!$B$2+Fares!$B$6-3.2,1)-0.000000001,0)))+1)) | G4: =Rides!$B$2/Rides!$B$41*Rides!$B$7/Rides!$B$41*(Fares!$C$2+Fares!$C$7-INDEX(Fares!$C$2:$C$40,MIN(38,MAX(0,ROUNDUP(ROUND(Fares!$B$2+Fares!$B$7-3.2,1)-0.000000001,0)))+1)) | H4: =Rides!$B$2/Rides!$B$41*Rides!$B$8/Rides!$B$41*(Fares!$C$2+Fares!$C$8-INDEX(Fares!$C$2:$C$40,MIN(38,MAX(0,ROUNDUP(ROUND(Fares!$B$2+Fares!$B$8-3.2,1)-0.000000001,0)))+1)) | I4: =Rides!$B$2/Rides!$B$41*Rides!$B$9/Rides!$B$41*(Fares!$C$2+Fares!$C$9-INDEX(Fares!$C$2:$C$40,MIN(38,MAX(0,ROUNDUP(ROUND(Fares!$B$2+Fares!$B$9-3.2,1)-0.000000001,0)))+1)) | J4: =Rides!$B$2/Rides!$B$41*Rides!$B$10/Rides!$B$41*(Fares!$C$2+Fares!$C$10-INDEX(Fares!$C$2:$C$40,MIN(38,MAX(0,ROUNDUP(ROUND(Fares!$B$2+Fares!$B$10-3.2,1)-0.000000001,0)))+1)) | K4: =Rides!$B$2/Rides!$B$41*Rides!$B$11/Rides!$B$41*(Fares!$C$2+Fares!$C$11-INDEX(Fares!$C$2:$C$40,MIN(38,MAX(0,ROUNDUP(ROUND(Fares!$B$2+Fares!$B$11-3.2,1)-0.000000001,0)))+1)) | L4: =Rides!$B$2/Rides!$B$41*Rides!$B$12/Rides!$B$41*(Fares!$C$2+Fares!$C$12-INDEX(Fares!$C$2:$C$40,MIN(38,MAX(0,ROUNDUP(ROUND(Fares!$B$2+Fares!$B$12-3.2,1)-0.000000001,0)))+1)) | M4: =Rides!$B$2/Rides!$B$41*Rides!$B$13/Rides!$B$41*(Fares!$C$2+Fares!$C$13-INDEX(Fares!$C$2:$C$40,MIN(38,MAX(0,ROUNDUP(ROUND(Fares!$B$2+Fares!$B$13-3.2,1)-0.000000001,0)))+1)) | N4: =Rides!$B$2/Rides!$B$41*Rides!$B$14/Rides!$B$41*(Fares!$C$2+Fares!$C$14-INDEX(Fares!$C$2:$C$40,MIN(38,MAX(0,ROUNDUP(ROUND(Fares!$B$2+Fares!$B$14-3.2,1)-0.000000001,0)))+1)) | O4: =Rides!$B$2/Rides!$B$41*Rides!$B$15/Rides!$B$41*(Fares!$C$2+Fares!$C$15-INDEX(Fares!$C$2:$C$40,MIN(38,MAX(0,ROUNDUP(ROUND(Fares!$B$2+Fares!$B$15-3.2,1)-0.000000001,0)))+1)) | P4: =Rides!$B$2/Rides!$B$41*Rides!$B$16/Rides!$B$41*(Fares!$C$2+Fares!$C$16-INDEX(Fares!$C$2:$C$40,MIN(38,MAX(0,ROUNDUP(ROUND(Fares!$B$2+Fares!$B$16-3.2,1)-0.000000001,0)))+1)) | Q4: =Rides!$B$2/Rides!$B$41*Rides!$B$17/Rides!$B$41*(Fares!$C$2+Fares!$C$17-INDEX(Fares!$C$2:$C$40,MIN(38,MAX(0,ROUNDUP(ROUND(Fares!$B$2+Fares!$B$17-3.2,1)-0.000000001,0)))+1)) | R4: =Rides!$B$2/Rides!$B$41*Rides!$B$18/Rides!$B$41*(Fares!$C$2+Fares!$C$18-INDEX(Fares!$C$2:$C$40,MIN(38,MAX(0,ROUNDUP(ROUND(Fares!$B$2+Fares!$B$18-3.2,1)-0.000000001,0)))+1)) | S4: =Rides!$B$2/Rides!$B$41*Rides!$B$19/Rides!$B$41*(Fares!$C$2+Fares!$C$19-INDEX(Fares!$C$2:$C$40,MIN(38,MAX(0,ROUNDUP(ROUND(Fares!$B$2+Fares!$B$19-3.2,1)-0.000000001,0)))+1)) | T4: =Rides!$B$2/Rides!$B$41*Rides!$B$20/Rides!$B$41*(Fares!$C$2+Fares!$C$20-INDEX(Fares!$C$2:$C$40,MIN(38,MAX(0,ROUNDUP(ROUND(Fares!$B$2+Fares!$B$20-3.2,1)-0.000000001,0)))+1)) | U4: =Rides!$B$2/Rides!$B$41*Rides!$B$21/Rides!$B$41*(Fares!$C$2+Fares!$C$21-INDEX(Fares!$C$2:$C$40,MIN(38,MAX(0,ROUNDUP(ROUND(Fares!$B$2+Fares!$B$21-3.2,1)-0.000000001,0)))+1)) | V4: =Rides!$B$2/Rides!$B$41*Rides!$B$22/Rides!$B$41*(Fares!$C$2+Fares!$C$22-INDEX(Fares!$C$2:$C$40,MIN(38,MAX(0,ROUNDUP(ROUND(Fares!$B$2+Fares!$B$22-3.2,1)-0.000000001,0)))+1)) | W4: =Rides!$B$2/Rides!$B$41*Rides!$B$23/Rides!$B$41*(Fares!$C$2+Fares!$C$23-INDEX(Fares!$C$2:$C$40,MIN(38,MAX(0,ROUNDUP(ROUND(Fares!$B$2+Fares!$B$23-3.2,1)-0.000000001,0)))+1)) | X4: =Rides!$B$2/Rides!$B$41*Rides!$B$24/Rides!$B$41*(Fares!$C$2+Fares!$C$24-INDEX(Fares!$C$2:$C$40,MIN(38,MAX(0,ROUNDUP(ROUND(Fares!$B$2+Fares!$B$24-3.2,1)-0.000000001,0)))+1)) | Y4: =Rides!$B$2/Rides!$B$41*Rides!$B$25/Rides!$B$41*(Fares!$C$2+Fares!$C$25-INDEX(Fares!$C$2:$C$40,MIN(38,MAX(0,ROUNDUP(ROUND(Fares!$B$2+Fares!$B$25-3.2,1)-0.000000001,0)))+1)) | Z4: =Rides!$B$2/Rides!$B$41*Rides!$B$26/Rides!$B$41*(Fares!$C$2+Fares!$C$26-INDEX(Fares!$C$2:$C$40,MIN(38,MAX(0,ROUNDUP(ROUND(Fares!$B$2+Fares!$B$26-3.2,1)-0.000000001,0)))+1)) | AA4: =Rides!$B$2/Rides!$B$41*Rides!$B$27/Rides!$B$41*(Fares!$C$2+Fares!$C$27-INDEX(Fares!$C$2:$C$40,MIN(38,MAX(0,ROUNDUP(ROUND(Fares!$B$2+Fares!$B$27-3.2,1)-0.000000001,0)))+1)) | AB4: =Rides!$B$2/Rides!$B$41*Rides!$B$28/Rides!$B$41*(Fares!$C$2+Fares!$C$28-INDEX(Fares!$C$2:$C$40,MIN(38,MAX(0,ROUNDUP(ROUND(Fares!$B$2+Fares!$B$28-3.2,1)-0.000000001,0)))+1)) | AC4: =Rides!$B$2/Rides!$B$41*Rides!$B$29/Rides!$B$41*(Fares!$C$2+Fares!$C$29-INDEX(Fares!$C$2:$C$40,MIN(38,MAX(0,ROUNDUP(ROUND(Fares!$B$2+Fares!$B$29-3.2,1)-0.000000001,0)))+1)) | AD4: =Rides!$B$2/Rides!$B$41*Rides!$B$30/Rides!$B$41*(Fares!$C$2+Fares!$C$30-INDEX(Fares!$C$2:$C$40,MIN(38,MAX(0,ROUNDUP(ROUND(Fares!$B$2+Fares!$B$30-3.2,1)-0.000000001,0)))+1)) | AE4: =Rides!$B$2/Rides!$B$41*Rides!$B$31/Rides!$B$41*(Fares!$C$2+Fares!$C$31-INDEX(Fares!$C$2:$C$40,MIN(38,MAX(0,ROUNDUP(ROUND(Fares!$B$2+Fares!$B$31-3.2,1)-0.000000001,0)))+1)) | AF4: =Rides!$B$2/Rides!$B$41*Rides!$B$32/Rides!$B$41*(Fares!$C$2+Fares!$C$32-INDEX(Fares!$C$2:$C$40,MIN(38,MAX(0,ROUNDUP(ROUND(Fares!$B$2+Fares!$B$32-3.2,1)-0.000000001,0)))+1)) | AG4: =Rides!$B$2/Rides!$B$41*Rides!$B$33/Rides!$B$41*(Fares!$C$2+Fares!$C$33-INDEX(Fares!$C$2:$C$40,MIN(38,MAX(0,ROUNDUP(ROUND(Fares!$B$2+Fares!$B$33-3.2,1)-0.000000001,0)))+1)) | AH4: =Rides!$B$2/Rides!$B$41*Rides!$B$34/Rides!$B$41*(Fares!$C$2+Fares!$C$34-INDEX(Fares!$C$2:$C$40,MIN(38,MAX(0,ROUNDUP(ROUND(Fares!$B$2+Fares!$B$34-3.2,1)-0.000000001,0)))+1)) | AI4: =Rides!$B$2/Rides!$B$41*Rides!$B$35/Rides!$B$41*(Fares!$C$2+Fares!$C$35-INDEX(Fares!$C$2:$C$40,MIN(38,MAX(0,ROUNDUP(ROUND(Fares!$B$2+Fares!$B$35-3.2,1)-0.000000001,0)))+1)) | AJ4: =Rides!$B$2/Rides!$B$41*Rides!$B$36/Rides!$B$41*(Fares!$C$2+Fares!$C$36-INDEX(Fares!$C$2:$C$40,MIN(38,MAX(0,ROUNDUP(ROUND(Fares!$B$2+Fares!$B$36-3.2,1)-0.000000001,0)))+1)) | AK4: =Rides!$B$2/Rides!$B$41*Rides!$B$37/Rides!$B$41*(Fares!$C$2+Fares!$C$37-INDEX(Fares!$C$2:$C$40,MIN(38,MAX(0,ROUNDUP(ROUND(Fares!$B$2+Fares!$B$37-3.2,1)-0.000000001,0)))+1)) | AL4: =Rides!$B$2/Rides!$B$41*Rides!$B$38/Rides!$B$41*(Fares!$C$2+Fares!$C$38-INDEX(Fares!$C$2:$C$40,MIN(38,MAX(0,ROUNDUP(ROUND(Fares!$B$2+Fares!$B$38-3.2,1)-0.000000001,0)))+1)) | AM4: =Rides!$B$2/Rides!$B$41*Rides!$B$39/Rides!$B$41*(Fares!$C$2+Fares!$C$39-INDEX(Fares!$C$2:$C$40,MIN(38,MAX(0,ROUNDUP(ROUND(Fares!$B$2+Fares!$B$39-3.2,1)-0.000000001,0)))+1)) | AN4: =Rides!$B$2/Rides!$B$41*Rides!$B$40/Rides!$B$41*(Fares!$C$2+Fares!$C$40-INDEX(Fares!$C$2:$C$40,MIN(38,MAX(0,ROUNDUP(ROUND(Fares!$B$2+Fares!$B$40-3.2,1)-0.000000001,0)))+1))
A5: =Fares!$B$3 | B5: =Rides!$B$3/Rides!$B$41*Rides!$B$2/Rides!$B$41*(Fares!$C$3+Fares!$C$2-INDEX(Fares!$C$2:$C$40,MIN(38,MAX(0,ROUNDUP(ROUND(Fares!$B$3+Fares!$B$2-3.2,1)-0.000000001,0)))+1)) | C5: =Rides!$B$3/Rides!$B$41*Rides!$B$3/Rides!$B$41*(Fares!$C$3+Fares!$C$3-INDEX(Fares!$C$2:$C$40,MIN(38,MAX(0,ROUNDUP(ROUND(Fares!$B$3+Fares!$B$3-3.2,1)-0.000000001,0)))+1)) | D5: =Rides!$B$3/Rides!$B$41*Rides!$B$4/Rides!$B$41*(Fares!$C$3+Fares!$C$4-INDEX(Fares!$C$2:$C$40,MIN(38,MAX(0,ROUNDUP(ROUND(Fares!$B$3+Fares!$B$4-3.2,1)-0.000000001,0)))+1)) | E5: =Rides!$B$3/Rides!$B$41*Rides!$B$5/Rides!$B$41*(Fares!$C$3+Fares!$C$5-INDEX(Fares!$C$2:$C$40,MIN(38,MAX(0,ROUNDUP(ROUND(Fares!$B$3+Fares!$B$5-3.2,1)-0.000000001,0)))+1)) | F5: =Rides!$B$3/Rides!$B$41*Rides!$B$6/Rides!$B$41*(Fares!$C$3+Fares!$C$6-INDEX(Fares!$C$2:$C$40,MIN(38,MAX(0,ROUNDUP(ROUND(Fares!$B$3+Fares!$B$6-3.2,1)-0.000000001,0)))+1)) | G5: =Rides!$B$3/Rides!$B$41*Rides!$B$7/Rides!$B$41*(Fares!$C$3+Fares!$C$7-INDEX(Fares!$C$2:$C$40,MIN(38,MAX(0,ROUNDUP(ROUND(Fares!$B$3+Fares!$B$7-3.2,1)-0.000000001,0)))+1)) | H5: =Rides!$B$3/Rides!$B$41*Rides!$B$8/Rides!$B$41*(Fares!$C$3+Fares!$C$8-INDEX(Fares!$C$2:$C$40,MIN(38,MAX(0,ROUNDUP(ROUND(Fares!$B$3+Fares!$B$8-3.2,1)-0.000000001,0)))+1)) | I5: =Rides!$B$3/Rides!$B$41*Rides!$B$9/Rides!$B$41*(Fares!$C$3+Fares!$C$9-INDEX(Fares!$C$2:$C$40,MIN(38,MAX(0,ROUNDUP(ROUND(Fares!$B$3+Fares!$B$9-3.2,1)-0.000000001,0)))+1)) | J5: =Rides!$B$3/Rides!$B$41*Rides!$B$10/Rides!$B$41*(Fares!$C$3+Fares!$C$10-INDEX(Fares!$C$2:$C$40,MIN(38,MAX(0,ROUNDUP(ROUND(Fares!$B$3+Fares!$B$10-3.2,1)-0.000000001,0)))+1)) | K5: =Rides!$B$3/Rides!$B$41*Rides!$B$11/Rides!$B$41*(Fares!$C$3+Fares!$C$11-INDEX(Fares!$C$2:$C$40,MIN(38,MAX(0,ROUNDUP(ROUND(Fares!$B$3+Fares!$B$11-3.2,1)-0.000000001,0)))+1)) | L5: =Rides!$B$3/Rides!$B$41*Rides!$B$12/Rides!$B$41*(Fares!$C$3+Fares!$C$12-INDEX(Fares!$C$2:$C$40,MIN(38,MAX(0,ROUNDUP(ROUND(Fares!$B$3+Fares!$B$12-3.2,1)-0.000000001,0)))+1)) | M5: =Rides!$B$3/Rides!$B$41*Rides!$B$13/Rides!$B$41*(Fares!$C$3+Fares!$C$13-INDEX(Fares!$C$2:$C$40,MIN(38,MAX(0,ROUNDUP(ROUND(Fares!$B$3+Fares!$B$13-3.2,1)-0.000000001,0)))+1)) | N5: =Rides!$B$3/Rides!$B$41*Rides!$B$14/Rides!$B$41*(Fares!$C$3+Fares!$C$14-INDEX(Fares!$C$2:$C$40,MIN(38,MAX(0,ROUNDUP(ROUND(Fares!$B$3+Fares!$B$14-3.2,1)-0.000000001,0)))+1)) | O5: =Rides!$B$3/Rides!$B$41*Rides!$B$15/Rides!$B$41*(Fares!$C$3+Fares!$C$15-INDEX(Fares!$C$2:$C$40,MIN(38,MAX(0,ROUNDUP(ROUND(Fares!$B$3+Fares!$B$15-3.2,1)-0.000000001,0)))+1)) | P5: =Rides!$B$3/Rides!$B$41*Rides!$B$16/Rides!$B$41*(Fares!$C$3+Fares!$C$16-INDEX(Fares!$C$2:$C$40,MIN(38,MAX(0,ROUNDUP(ROUND(Fares!$B$3+Fares!$B$16-3.2,1)-0.000000001,0)))+1)) | Q5: =Rides!$B$3/Rides!$B$41*Rides!$B$17/Rides!$B$41*(Fares!$C$3+Fares!$C$17-INDEX(Fares!$C$2:$C$40,MIN(38,MAX(0,ROUNDUP(ROUND(Fares!$B$3+Fares!$B$17-3.2,1)-0.000000001,0)))+1)) | R5: =Rides!$B$3/Rides!$B$41*Rides!$B$18/Rides!$B$41*(Fares!$C$3+Fares!$C$18-INDEX(Fares!$C$2:$C$40,MIN(38,MAX(0,ROUNDUP(ROUND(Fares!$B$3+Fares!$B$18-3.2,1)-0.000000001,0)))+1)) | S5: =Rides!$B$3/Rides!$B$41*Rides!$B$19/Rides!$B$41*(Fares!$C$3+Fares!$C$19-INDEX(Fares!$C$2:$C$40,MIN(38,MAX(0,ROUNDUP(ROUND(Fares!$B$3+Fares!$B$19-3.2,1)-0.000000001,0)))+1)) | T5: =Rides!$B$3/Rides!$B$41*Rides!$B$20/Rides!$B$41*(Fares!$C$3+Fares!$C$20-INDEX(Fares!$C$2:$C$40,MIN(38,MAX(0,ROUNDUP(ROUND(Fares!$B$3+Fares!$B$20-3.2,1)-0.000000001,0)))+1)) | U5: =Rides!$B$3/Rides!$B$41*Rides!$B$21/Rides!$B$41*(Fares!$C$3+Fares!$C$21-INDEX(Fares!$C$2:$C$40,MIN(38,MAX(0,ROUNDUP(ROUND(Fares!$B$3+Fares!$B$21-3.2,1)-0.000000001,0)))+1)) | V5: =Rides!$B$3/Rides!$B$41*Rides!$B$22/Rides!$B$41*(Fares!$C$3+Fares!$C$22-INDEX(Fares!$C$2:$C$40,MIN(38,MAX(0,ROUNDUP(ROUND(Fares!$B$3+Fares!$B$22-3.2,1)-0.000000001,0)))+1)) | W5: =Rides!$B$3/Rides!$B$41*Rides!$B$23/Rides!$B$41*(Fares!$C$3+Fares!$C$23-INDEX(Fares!$C$2:$C$40,MIN(38,MAX(0,ROUNDUP(ROUND(Fares!$B$3+Fares!$B$23-3.2,1)-0.000000001,0)))+1)) | X5: =Rides!$B$3/Rides!$B$41*Rides!$B$24/Rides!$B$41*(Fares!$C$3+Fares!$C$24-INDEX(Fares!$C$2:$C$40,MIN(38,MAX(0,ROUNDUP(ROUND(Fares!$B$3+Fares!$B$24-3.2,1)-0.000000001,0)))+1)) | Y5: =Rides!$B$3/Rides!$B$41*Rides!$B$25/Rides!$B$41*(Fares!$C$3+Fares!$C$25-INDEX(Fares!$C$2:$C$40,MIN(38,MAX(0,ROUNDUP(ROUND(Fares!$B$3+Fares!$B$25-3.2,1)-0.000000001,0)))+1)) | Z5: =Rides!$B$3/Rides!$B$41*Rides!$B$26/Rides!$B$41*(Fares!$C$3+Fares!$C$26-INDEX(Fares!$C$2:$C$40,MIN(38,MAX(0,ROUNDUP(ROUND(Fares!$B$3+Fares!$B$26-3.2,1)-0.000000001,0)))+1)) | AA5: =Rides!$B$3/Rides!$B$41*Rides!$B$27/Rides!$B$41*(Fares!$C$3+Fares!$C$27-INDEX(Fares!$C$2:$C$40,MIN(38,MAX(0,ROUNDUP(ROUND(Fares!$B$3+Fares!$B$27-3.2,1)-0.000000001,0)))+1)) | AB5: =Rides!$B$3/Rides!$B$41*Rides!$B$28/Rides!$B$41*(Fares!$C$3+Fares!$C$28-INDEX(Fares!$C$2:$C$40,MIN(38,MAX(0,ROUNDUP(ROUND(Fares!$B$3+Fares!$B$28-3.2,1)-0.000000001,0)))+1)) | AC5: =Rides!$B$3/Rides!$B$41*Rides!$B$29/Rides!$B$41*(Fares!$C$3+Fares!$C$29-INDEX(Fares!$C$2:$C$40,MIN(38,MAX(0,ROUNDUP(ROUND(Fares!$B$3+Fares!$B$29-3.2,1)-0.000000001,0)))+1)) | AD5: =Rides!$B$3/Rides!$B$41*Rides!$B$30/Rides!$B$41*(Fares!$C$3+Fares!$C$30-INDEX(Fares!$C$2:$C$40,MIN(38,MAX(0,ROUNDUP(ROUND(Fares!$B$3+Fares!$B$30-3.2,1)-0.000000001,0)))+1)) | AE5: =Rides!$B$3/Rides!$B$41*Rides!$B$31/Rides!$B$41*(Fares!$C$3+Fares!$C$31-INDEX(Fares!$C$2:$C$40,MIN(38,MAX(0,ROUNDUP(ROUND(Fares!$B$3+Fares!$B$31-3.2,1)-0.000000001,0)))+1)) | AF5: =Rides!$B$3/Rides!$B$41*Rides!$B$32/Rides!$B$41*(Fares!$C$3+Fares!$C$32-INDEX(Fares!$C$2:$C$40,MIN(38,MAX(0,ROUNDUP(ROUND(Fares!$B$3+Fares!$B$32-3.2,1)-0.000000001,0)))+1)) | AG5: =Rides!$B$3/Rides!$B$41*Rides!$B$33/Rides!$B$41*(Fares!$C$3+Fares!$C$33-INDEX(Fares!$C$2:$C$40,MIN(38,MAX(0,ROUNDUP(ROUND(Fares!$B$3+Fares!$B$33-3.2,1)-0.000000001,0)))+1)) | AH5: =Rides!$B$3/Rides!$B$41*Rides!$B$34/Rides!$B$41*(Fares!$C$3+Fares!$C$34-INDEX(Fares!$C$2:$C$40,MIN(38,MAX(0,ROUNDUP(ROUND(Fares!$B$3+Fares!$B$34-3.2,1)-0.000000001,0)))+1)) | AI5: =Rides!$B$3/Rides!$B$41*Rides!$B$35/Rides!$B$41*(Fares!$C$3+Fares!$C$35-INDEX(Fares!$C$2:$C$40,MIN(38,MAX(0,ROUNDUP(ROUND(Fares!$B$3+Fares!$B$35-3.2,1)-0.000000001,0)))+1)) | AJ5: =Rides!$B$3/Rides!$B$41*Rides!$B$36/Rides!$B$41*(Fares!$C$3+Fares!$C$36-INDEX(Fares!$C$2:$C$40,MIN(38,MAX(0,ROUNDUP(ROUND(Fares!$B$3+Fares!$B$36-3.2,1)-0.000000001,0)))+1)) | AK5: =Rides!$B$3/Rides!$B$41*Rides!$B$37/Rides!$B$41*(Fares!$C$3+Fares!$C$37-INDEX(Fares!$C$2:$C$40,MIN(38,MAX(0,ROUNDUP(ROUND(Fares!$B$3+Fares!$B$37-3.2,1)-0.000000001,0)))+1)) | AL5: =Rides!$B$3/Rides!$B$41*Rides!$B$38/Rides!$B$41*(Fares!$C$3+Fares!$C$38-INDEX(Fares!$C$2:$C$40,MIN(38,MAX(0,ROUNDUP(ROUND(Fares!$B$3+Fares!$B$38-3.2,1)-0.000000001,0)))+1)) | AM5: =Rides!$B$3/Rides!$B$41*Rides!$B$39/Rides!$B$41*(Fares!$C$3+Fares!$C$39-INDEX(Fares!$C$2:$C$40,MIN(38,MAX(0,ROUNDUP(ROUND(Fares!$B$3+Fares!$B$39-3.2,1)-0.000000001,0)))+1)) | AN5: =Rides!$B$3/Rides!$B$41*Rides!$B$40/Rides!$B$41*(Fares!$C$3+Fares!$C$40-INDEX(Fares!$C$2:$C$40,MIN(38,MAX(0,ROUNDUP(ROUND(Fares!$B$3+Fares!$B$40-3.2,1)-0.000000001,0)))+1))
A6: =Fares!$B$4 | B6: =Rides!$B$4/Rides!$B$41*Rides!$B$2/Rides!$B$41*(Fares!$C$4+Fares!$C$2-INDEX(Fares!$C$2:$C$40,MIN(38,MAX(0,ROUNDUP(ROUND(Fares!$B$4+Fares!$B$2-3.2,1)-0.000000001,0)))+1)) | C6: =Rides!$B$4/Rides!$B$41*Rides!$B$3/Rides!$B$41*(Fares!$C$4+Fares!$C$3-INDEX(Fares!$C$2:$C$40,MIN(38,MAX(0,ROUNDUP(ROUND(Fares!$B$4+Fares!$B$3-3.2,1)-0.000000001,0)))+1)) | D6: =Rides!$B$4/Rides!$B$41*Rides!$B$4/Rides!$B$41*(Fares!$C$4+Fares!$C$4-INDEX(Fares!$C$2:$C$40,MIN(38,MAX(0,ROUNDUP(ROUND(Fares!$B$4+Fares!$B$4-3.2,1)-0.000000001,0)))+1)) | E6: =Rides!$B$4/Rides!$B$41*Rides!$B$5/Rides!$B$41*(Fares!$C$4+Fares!$C$5-INDEX(Fares!$C$2:$C$40,MIN(38,MAX(0,ROUNDUP(ROUND(Fares!$B$4+Fares!$B$5-3.2,1)-0.000000001,0)))+1)) | F6: =Rides!$B$4/Rides!$B$41*Rides!$B$6/Rides!$B$41*(Fares!$C$4+Fares!$C$6-INDEX(Fares!$C$2:$C$40,MIN(38,MAX(0,ROUNDUP(ROUND(Fares!$B$4+Fares!$B$6-3.2,1)-0.000000001,0)))+1)) | G6: =Rides!$B$4/Rides!$B$41*Rides!$B$7/Rides!$B$41*(Fares!$C$4+Fares!$C$7-INDEX(Fares!$C$2:$C$40,MIN(38,MAX(0,ROUNDUP(ROUND(Fares!$B$4+Fares!$B$7-3.2,1)-0.000000001,0)))+1)) | H6: =Rides!$B$4/Rides!$B$41*Rides!$B$8/Rides!$B$41*(Fares!$C$4+Fares!$C$8-INDEX(Fares!$C$2:$C$40,MIN(38,MAX(0,ROUNDUP(ROUND(Fares!$B$4+Fares!$B$8-3.2,1)-0.000000001,0)))+1)) | I6: =Rides!$B$4/Rides!$B$41*Rides!$B$9/Rides!$B$41*(Fares!$C$4+Fares!$C$9-INDEX(Fares!$C$2:$C$40,MIN(38,MAX(0,ROUNDUP(ROUND(Fares!$B$4+Fares!$B$9-3.2,1)-0.000000001,0)))+1)) | J6: =Rides!$B$4/Rides!$B$41*Rides!$B$10/Rides!$B$41*(Fares!$C$4+Fares!$C$10-INDEX(Fares!$C$2:$C$40,MIN(38,MAX(0,ROUNDUP(ROUND(Fares!$B$4+Fares!$B$10-3.2,1)-0.000000001,0)))+1)) | K6: =Rides!$B$4/Rides!$B$41*Rides!$B$11/Rides!$B$41*(Fares!$C$4+Fares!$C$11-INDEX(Fares!$C$2:$C$40,MIN(38,MAX(0,ROUNDUP(ROUND(Fares!$B$4+Fares!$B$11-3.2,1)-0.000000001,0)))+1)) | L6: =Rides!$B$4/Rides!$B$41*Rides!$B$12/Rides!$B$41*(Fares!$C$4+Fares!$C$12-INDEX(Fares!$C$2:$C$40,MIN(38,MAX(0,ROUNDUP(ROUND(Fares!$B$4+Fares!$B$12-3.2,1)-0.000000001,0)))+1)) | M6: =Rides!$B$4/Rides!$B$41*Rides!$B$13/Rides!$B$41*(Fares!$C$4+Fares!$C$13-INDEX(Fares!$C$2:$C$40,MIN(38,MAX(0,ROUNDUP(ROUND(Fares!$B$4+Fares!$B$13-3.2,1)-0.000000001,0)))+1)) | N6: =Rides!$B$4/Rides!$B$41*Rides!$B$14/Rides!$B$41*(Fares!$C$4+Fares!$C$14-INDEX(Fares!$C$2:$C$40,MIN(38,MAX(0,ROUNDUP(ROUND(Fares!$B$4+Fares!$B$14-3.2,1)-0.000000001,0)))+1)) | O6: =Rides!$B$4/Rides!$B$41*Rides!$B$15/Rides!$B$41*(Fares!$C$4+Fares!$C$15-INDEX(Fares!$C$2:$C$40,MIN(38,MAX(0,ROUNDUP(ROUND(Fares!$B$4+Fares!$B$15-3.2,1)-0.000000001,0)))+1)) | P6: =Rides!$B$4/Rides!$B$41*Rides!$B$16/Rides!$B$41*(Fares!$C$4+Fares!$C$16-INDEX(Fares!$C$2:$C$40,MIN(38,MAX(0,ROUNDUP(ROUND(Fares!$B$4+Fares!$B$16-3.2,1)-0.000000001,0)))+1)) | Q6: =Rides!$B$4/Rides!$B$41*Rides!$B$17/Rides!$B$41*(Fares!$C$4+Fares!$C$17-INDEX(Fares!$C$2:$C$40,MIN(38,MAX(0,ROUNDUP(ROUND(Fares!$B$4+Fares!$B$17-3.2,1)-0.000000001,0)))+1)) | R6: =Rides!$B$4/Rides!$B$41*Rides!$B$18/Rides!$B$41*(Fares!$C$4+Fares!$C$18-INDEX(Fares!$C$2:$C$40,MIN(38,MAX(0,ROUNDUP(ROUND(Fares!$B$4+Fares!$B$18-3.2,1)-0.000000001,0)))+1)) | S6: =Rides!$B$4/Rides!$B$41*Rides!$B$19/Rides!$B$41*(Fares!$C$4+Fares!$C$19-INDEX(Fares!$C$2:$C$40,MIN(38,MAX(0,ROUNDUP(ROUND(Fares!$B$4+Fares!$B$19-3.2,1)-0.000000001,0)))+1)) | T6: =Rides!$B$4/Rides!$B$41*Rides!$B$20/Rides!$B$41*(Fares!$C$4+Fares!$C$20-INDEX(Fares!$C$2:$C$40,MIN(38,MAX(0,ROUNDUP(ROUND(Fares!$B$4+Fares!$B$20-3.2,1)-0.000000001,0)))+1)) | U6: =Rides!$B$4/Rides!$B$41*Rides!$B$21/Rides!$B$41*(Fares!$C$4+Fares!$C$21-INDEX(Fares!$C$2:$C$40,MIN(38,MAX(0,ROUNDUP(ROUND(Fares!$B$4+Fares!$B$21-3.2,1)-0.000000001,0)))+1)) | V6: =Rides!$B$4/Rides!$B$41*Rides!$B$22/Rides!$B$41*(Fares!$C$4+Fares!$C$22-INDEX(Fares!$C$2:$C$40,MIN(38,MAX(0,ROUNDUP(ROUND(Fares!$B$4+Fares!$B$22-3.2,1)-0.000000001,0)))+1)) | W6: =Rides!$B$4/Rides!$B$41*Rides!$B$23/Rides!$B$41*(Fares!$C$4+Fares!$C$23-INDEX(Fares!$C$2:$C$40,MIN(38,MAX(0,ROUNDUP(ROUND(Fares!$B$4+Fares!$B$23-3.2,1)-0.000000001,0)))+1)) | X6: =Rides!$B$4/Rides!$B$41*Rides!$B$24/Rides!$B$41*(Fares!$C$4+Fares!$C$24-INDEX(Fares!$C$2:$C$40,MIN(38,MAX(0,ROUNDUP(ROUND(Fares!$B$4+Fares!$B$24-3.2,1)-0.000000001,0)))+1)) | Y6: =Rides!$B$4/Rides!$B$41*Rides!$B$25/Rides!$B$41*(Fares!$C$4+Fares!$C$25-INDEX(Fares!$C$2:$C$40,MIN(38,MAX(0,ROUNDUP(ROUND(Fares!$B$4+Fares!$B$25-3.2,1)-0.000000001,0)))+1)) | Z6: =Rides!$B$4/Rides!$B$41*Rides!$B$26/Rides!$B$41*(Fares!$C$4+Fares!$C$26-INDEX(Fares!$C$2:$C$40,MIN(38,MAX(0,ROUNDUP(ROUND(Fares!$B$4+Fares!$B$26-3.2,1)-0.000000001,0)))+1)) | AA6: =Rides!$B$4/Rides!$B$41*Rides!$B$27/Rides!$B$41*(Fares!$C$4+Fares!$C$27-INDEX(Fares!$C$2:$C$40,MIN(38,MAX(0,ROUNDUP(ROUND(Fares!$B$4+Fares!$B$27-3.2,1)-0.000000001,0)))+1)) | AB6: =Rides!$B$4/Rides!$B$41*Rides!$B$28/Rides!$B$41*(Fares!$C$4+Fares!$C$28-INDEX(Fares!$C$2:$C$40,MIN(38,MAX(0,ROUNDUP(ROUND(Fares!$B$4+Fares!$B$28-3.2,1)-0.000000001,0)))+1)) | AC6: =Rides!$B$4/Rides!$B$41*Rides!$B$29/Rides!$B$41*(Fares!$C$4+Fares!$C$29-INDEX(Fares!$C$2:$C$40,MIN(38,MAX(0,ROUNDUP(ROUND(Fares!$B$4+Fares!$B$29-3.2,1)-0.000000001,0)))+1)) | AD6: =Rides!$B$4/Rides!$B$41*Rides!$B$30/Rides!$B$41*(Fares!$C$4+Fares!$C$30-INDEX(Fares!$C$2:$C$40,MIN(38,MAX(0,ROUNDUP(ROUND(Fares!$B$4+Fares!$B$30-3.2,1)-0.000000001,0)))+1)) | AE6: =Rides!$B$4/Rides!$B$41*Rides!$B$31/Rides!$B$41*(Fares!$C$4+Fares!$C$31-INDEX(Fares!$C$2:$C$40,MIN(38,MAX(0,ROUNDUP(ROUND(Fares!$B$4+Fares!$B$31-3.2,1)-0.000000001,0)))+1)) | AF6: =Rides!$B$4/Rides!$B$41*Rides!$B$32/Rides!$B$41*(Fares!$C$4+Fares!$C$32-INDEX(Fares!$C$2:$C$40,MIN(38,MAX(0,ROUNDUP(ROUND(Fares!$B$4+Fares!$B$32-3.2,1)-0.000000001,0)))+1)) | AG6: =Rides!$B$4/Rides!$B$41*Rides!$B$33/Rides!$B$41*(Fares!$C$4+Fares!$C$33-INDEX(Fares!$C$2:$C$40,MIN(38,MAX(0,ROUNDUP(ROUND(Fares!$B$4+Fares!$B$33-3.2,1)-0.000000001,0)))+1)) | AH6: =Rides!$B$4/Rides!$B$41*Rides!$B$34/Rides!$B$41*(Fares!$C$4+Fares!$C$34-INDEX(Fares!$C$2:$C$40,MIN(38,MAX(0,ROUNDUP(ROUND(Fares!$B$4+Fares!$B$34-3.2,1)-0.000000001,0)))+1)) | AI6: =Rides!$B$4/Rides!$B$41*Rides!$B$35/Rides!$B$41*(Fares!$C$4+Fares!$C$35-INDEX(Fares!$C$2:$C$40,MIN(38,MAX(0,ROUNDUP(ROUND(Fares!$B$4+Fares!$B$35-3.2,1)-0.000000001,0)))+1)) | AJ6: =Rides!$B$4/Rides!$B$41*Rides!$B$36/Rides!$B$41*(Fares!$C$4+Fares!$C$36-INDEX(Fares!$C$2:$C$40,MIN(38,MAX(0,ROUNDUP(ROUND(Fares!$B$4+Fares!$B$36-3.2,1)-0.000000001,0)))+1)) | AK6: =Rides!$B$4/Rides!$B$41*Rides!$B$37/Rides!$B$41*(Fares!$C$4+Fares!$C$37-INDEX(Fares!$C$2:$C$40,MIN(38,MAX(0,ROUNDUP(ROUND(Fares!$B$4+Fares!$B$37-3.2,1)-0.000000001,0)))+1)) | AL6: =Rides!$B$4/Rides!$B$41*Rides!$B$38/Rides!$B$41*(Fares!$C$4+Fares!$C$38-INDEX(Fares!$C$2:$C$40,MIN(38,MAX(0,ROUNDUP(ROUND(Fares!$B$4+Fares!$B$38-3.2,1)-0.000000001,0)))+1)) | AM6: =Rides!$B$4/Rides!$B$41*Rides!$B$39/Rides!$B$41*(Fares!$C$4+Fares!$C$39-INDEX(Fares!$C$2:$C$40,MIN(38,MAX(0,ROUNDUP(ROUND(Fares!$B$4+Fares!$B$39-3.2,1)-0.000000001,0)))+1)) | AN6: =Rides!$B$4/Rides!$B$41*Rides!$B$40/Rides!$B$41*(Fares!$C$4+Fares!$C$40-INDEX(Fares!$C$2:$C$40,MIN(38,MAX(0,ROUNDUP(ROUND(Fares!$B$4+Fares!$B$40-3.2,1)-0.000000001,0)))+1))
A7: =Fares!$B$5 | B7: =Rides!$B$5/Rides!$B$41*Rides!$B$2/Rides!$B$41*(Fares!$C$5+Fares!$C$2-INDEX(Fares!$C$2:$C$40,MIN(38,MAX(0,ROUNDUP(ROUND(Fares!$B$5+Fares!$B$2-3.2,1)-0.000000001,0)))+1)) | C7: =Rides!$B$5/Rides!$B$41*Rides!$B$3/Rides!$B$41*(Fares!$C$5+Fares!$C$3-INDEX(Fares!$C$2:$C$40,MIN(38,MAX(0,ROUNDUP(ROUND(Fares!$B$5+Fares!$B$3-3.2,1)-0.000000001,0)))+1)) | D7: =Rides!$B$5/Rides!$B$41*Rides!$B$4/Rides!$B$41*(Fares!$C$5+Fares!$C$4-INDEX(Fares!$C$2:$C$40,MIN(38,MAX(0,ROUNDUP(ROUND(Fares!$B$5+Fares!$B$4-3.2,1)-0.000000001,0)))+1)) | E7: =Rides!$B$5/Rides!$B$41*Rides!$B$5/Rides!$B$41*(Fares!$C$5+Fares!$C$5-INDEX(Fares!$C$2:$C$40,MIN(38,MAX(0,ROUNDUP(ROUND(Fares!$B$5+Fares!$B$5-3.2,1)-0.000000001,0)))+1)) | F7: =Rides!$B$5/Rides!$B$41*Rides!$B$6/Rides!$B$41*(Fares!$C$5+Fares!$C$6-INDEX(Fares!$C$2:$C$40,MIN(38,MAX(0,ROUNDUP(ROUND(Fares!$B$5+Fares!$B$6-3.2,1)-0.000000001,0)))+1)) | G7: =Rides!$B$5/Rides!$B$41*Rides!$B$7/Rides!$B$41*(Fares!$C$5+Fares!$C$7-INDEX(Fares!$C$2:$C$40,MIN(38,MAX(0,ROUNDUP(ROUND(Fares!$B$5+Fares!$B$7-3.2,1)-0.000000001,0)))+1)) | H7: =Rides!$B$5/Rides!$B$41*Rides!$B$8/Rides!$B$41*(Fares!$C$5+Fares!$C$8-INDEX(Fares!$C$2:$C$40,MIN(38,MAX(0,ROUNDUP(ROUND(Fares!$B$5+Fares!$B$8-3.2,1)-0.000000001,0)))+1)) | I7: =Rides!$B$5/Rides!$B$41*Rides!$B$9/Rides!$B$41*(Fares!$C$5+Fares!$C$9-INDEX(Fares!$C$2:$C$40,MIN(38,MAX(0,ROUNDUP(ROUND(Fares!$B$5+Fares!$B$9-3.2,1)-0.000000001,0)))+1)) | J7: =Rides!$B$5/Rides!$B$41*Rides!$B$10/Rides!$B$41*(Fares!$C$5+Fares!$C$10-INDEX(Fares!$C$2:$C$40,MIN(38,MAX(0,ROUNDUP(ROUND(Fares!$B$5+Fares!$B$10-3.2,1)-0.000000001,0)))+1)) | K7: =Rides!$B$5/Rides!$B$41*Rides!$B$11/Rides!$B$41*(Fares!$C$5+Fares!$C$11-INDEX(Fares!$C$2:$C$40,MIN(38,MAX(0,ROUNDUP(ROUND(Fares!$B$5+Fares!$B$11-3.2,1)-0.000000001,0)))+1)) | L7: =Rides!$B$5/Rides!$B$41*Rides!$B$12/Rides!$B$41*(Fares!$C$5+Fares!$C$12-INDEX(Fares!$C$2:$C$40,MIN(38,MAX(0,ROUNDUP(ROUND(Fares!$B$5+Fares!$B$12-3.2,1)-0.000000001,0)))+1)) | M7: =Rides!$B$5/Rides!$B$41*Rides!$B$13/Rides!$B$41*(Fares!$C$5+Fares!$C$13-INDEX(Fares!$C$2:$C$40,MIN(38,MAX(0,ROUNDUP(ROUND(Fares!$B$5+Fares!$B$13-3.2,1)-0.000000001,0)))+1)) | N7: =Rides!$B$5/Rides!$B$41*Rides!$B$14/Rides!$B$41*(Fares!$C$5+Fares!$C$14-INDEX(Fares!$C$2:$C$40,MIN(38,MAX(0,ROUNDUP(ROUND(Fares!$B$5+Fares!$B$14-3.2,1)-0.000000001,0)))+1)) | O7: =Rides!$B$5/Rides!$B$41*Rides!$B$15/Rides!$B$41*(Fares!$C$5+Fares!$C$15-INDEX(Fares!$C$2:$C$40,MIN(38,MAX(0,ROUNDUP(ROUND(Fares!$B$5+Fares!$B$15-3.2,1)-0.000000001,0)))+1)) | P7: =Rides!$B$5/Rides!$B$41*Rides!$B$16/Rides!$B$41*(Fares!$C$5+Fares!$C$16-INDEX(Fares!$C$2:$C$40,MIN(38,MAX(0,ROUNDUP(ROUND(Fares!$B$5+Fares!$B$16-3.2,1)-0.000000001,0)))+1)) | Q7: =Rides!$B$5/Rides!$B$41*Rides!$B$17/Rides!$B$41*(Fares!$C$5+Fares!$C$17-INDEX(Fares!$C$2:$C$40,MIN(38,MAX(0,ROUNDUP(ROUND(Fares!$B$5+Fares!$B$17-3.2,1)-0.000000001,0)))+1)) | R7: =Rides!$B$5/Rides!$B$41*Rides!$B$18/Rides!$B$41*(Fares!$C$5+Fares!$C$18-INDEX(Fares!$C$2:$C$40,MIN(38,MAX(0,ROUNDUP(ROUND(Fares!$B$5+Fares!$B$18-3.2,1)-0.000000001,0)))+1)) | S7: =Rides!$B$5/Rides!$B$41*Rides!$B$19/Rides!$B$41*(Fares!$C$5+Fares!$C$19-INDEX(Fares!$C$2:$C$40,MIN(38,MAX(0,ROUNDUP(ROUND(Fares!$B$5+Fares!$B$19-3.2,1)-0.000000001,0)))+1)) | T7: =Rides!$B$5/Rides!$B$41*Rides!$B$20/Rides!$B$41*(Fares!$C$5+Fares!$C$20-INDEX(Fares!$C$2:$C$40,MIN(38,MAX(0,ROUNDUP(ROUND(Fares!$B$5+Fares!$B$20-3.2,1)-0.000000001,0)))+1)) | U7: =Rides!$B$5/Rides!$B$41*Rides!$B$21/Rides!$B$41*(Fares!$C$5+Fares!$C$21-INDEX(Fares!$C$2:$C$40,MIN(38,MAX(0,ROUNDUP(ROUND(Fares!$B$5+Fares!$B$21-3.2,1)-0.000000001,0)))+1)) | V7: =Rides!$B$5/Rides!$B$41*Rides!$B$22/Rides!$B$41*(Fares!$C$5+Fares!$C$22-INDEX(Fares!$C$2:$C$40,MIN(38,MAX(0,ROUNDUP(ROUND(Fares!$B$5+Fares!$B$22-3.2,1)-0.000000001,0)))+1)) | W7: =Rides!$B$5/Rides!$B$41*Rides!$B$23/Rides!$B$41*(Fares!$C$5+Fares!$C$23-INDEX(Fares!$C$2:$C$40,MIN(38,MAX(0,ROUNDUP(ROUND(Fares!$B$5+Fares!$B$23-3.2,1)-0.000000001,0)))+1)) | X7: =Rides!$B$5/Rides!$B$41*Rides!$B$24/Rides!$B$41*(Fares!$C$5+Fares!$C$24-INDEX(Fares!$C$2:$C$40,MIN(38,MAX(0,ROUNDUP(ROUND(Fares!$B$5+Fares!$B$24-3.2,1)-0.000000001,0)))+1)) | Y7: =Rides!$B$5/Rides!$B$41*Rides!$B$25/Rides!$B$41*(Fares!$C$5+Fares!$C$25-INDEX(Fares!$C$2:$C$40,MIN(38,MAX(0,ROUNDUP(ROUND(Fares!$B$5+Fares!$B$25-3.2,1)-0.000000001,0)))+1)) | Z7: =Rides!$B$5/Rides!$B$41*Rides!$B$26/Rides!$B$41*(Fares!$C$5+Fares!$C$26-INDEX(Fares!$C$2:$C$40,MIN(38,MAX(0,ROUNDUP(ROUND(Fares!$B$5+Fares!$B$26-3.2,1)-0.000000001,0)))+1)) | AA7: =Rides!$B$5/Rides!$B$41*Rides!$B$27/Rides!$B$41*(Fares!$C$5+Fares!$C$27-INDEX(Fares!$C$2:$C$40,MIN(38,MAX(0,ROUNDUP(ROUND(Fares!$B$5+Fares!$B$27-3.2,1)-0.000000001,0)))+1)) | AB7: =Rides!$B$5/Rides!$B$41*Rides!$B$28/Rides!$B$41*(Fares!$C$5+Fares!$C$28-INDEX(Fares!$C$2:$C$40,MIN(38,MAX(0,ROUNDUP(ROUND(Fares!$B$5+Fares!$B$28-3.2,1)-0.000000001,0)))+1)) | AC7: =Rides!$B$5/Rides!$B$41*Rides!$B$29/Rides!$B$41*(Fares!$C$5+Fares!$C$29-INDEX(Fares!$C$2:$C$40,MIN(38,MAX(0,ROUNDUP(ROUND(Fares!$B$5+Fares!$B$29-3.2,1)-0.000000001,0)))+1)) | AD7: =Rides!$B$5/Rides!$B$41*Rides!$B$30/Rides!$B$41*(Fares!$C$5+Fares!$C$30-INDEX(Fares!$C$2:$C$40,MIN(38,MAX(0,ROUNDUP(ROUND(Fares!$B$5+Fares!$B$30-3.2,1)-0.000000001,0)))+1)) | AE7: =Rides!$B$5/Rides!$B$41*Rides!$B$31/Rides!$B$41*(Fares!$C$5+Fares!$C$31-INDEX(Fares!$C$2:$C$40,MIN(38,MAX(0,ROUNDUP(ROUND(Fares!$B$5+Fares!$B$31-3.2,1)-0.000000001,0)))+1)) | AF7: =Rides!$B$5/Rides!$B$41*Rides!$B$32/Rides!$B$41*(Fares!$C$5+Fares!$C$32-INDEX(Fares!$C$2:$C$40,MIN(38,MAX(0,ROUNDUP(ROUND(Fares!$B$5+Fares!$B$32-3.2,1)-0.000000001,0)))+1)) | AG7: =Rides!$B$5/Rides!$B$41*Rides!$B$33/Rides!$B$41*(Fares!$C$5+Fares!$C$33-INDEX(Fares!$C$2:$C$40,MIN(38,MAX(0,ROUNDUP(ROUND(Fares!$B$5+Fares!$B$33-3.2,1)-0.000000001,0)))+1)) | AH7: =Rides!$B$5/Rides!$B$41*Rides!$B$34/Rides!$B$41*(Fares!$C$5+Fares!$C$34-INDEX(Fares!$C$2:$C$40,MIN(38,MAX(0,ROUNDUP(ROUND(Fares!$B$5+Fares!$B$34-3.2,1)-0.000000001,0)))+1)) | AI7: =Rides!$B$5/Rides!$B$41*Rides!$B$35/Rides!$B$41*(Fares!$C$5+Fares!$C$35-INDEX(Fares!$C$2:$C$40,MIN(38,MAX(0,ROUNDUP(ROUND(Fares!$B$5+Fares!$B$35-3.2,1)-0.000000001,0)))+1)) | AJ7: =Rides!$B$5/Rides!$B$41*Rides!$B$36/Rides!$B$41*(Fares!$C$5+Fares!$C$36-INDEX(Fares!$C$2:$C$40,MIN(38,MAX(0,ROUNDUP(ROUND(Fares!$B$5+Fares!$B$36-3.2,1)-0.000000001,0)))+1)) | AK7: =Rides!$B$5/Rides!$B$41*Rides!$B$37/Rides!$B$41*(Fares!$C$5+Fares!$C$37-INDEX(Fares!$C$2:$C$40,MIN(38,MAX(0,ROUNDUP(ROUND(Fares!$B$5+Fares!$B$37-3.2,1)-0.000000001,0)))+1)) | AL7: =Rides!$B$5/Rides!$B$41*Rides!$B$38/Rides!$B$41*(Fares!$C$5+Fares!$C$38-INDEX(Fares!$C$2:$C$40,MIN(38,MAX(0,ROUNDUP(ROUND(Fares!$B$5+Fares!$B$38-3.2,1)-0.000000001,0)))+1)) | AM7: =Rides!$B$5/Rides!$B$41*Rides!$B$39/Rides!$B$41*(Fares!$C$5+Fares!$C$39-INDEX(Fares!$C$2:$C$40,MIN(38,MAX(0,ROUNDUP(ROUND(Fares!$B$5+Fares!$B$39-3.2,1)-0.000000001,0)))+1)) | AN7: =Rides!$B$5/Rides!$B$41*Rides!$B$40/Rides!$B$41*(Fares!$C$5+Fares!$C$40-INDEX(Fares!$C$2:$C$40,MIN(38,MAX(0,ROUNDUP(ROUND(Fares!$B$5+Fares!$B$40-3.2,1)-0.000000001,0)))+1))
